<robot name="leap">
  <link name="hand_base_link">
    <visual>
      <origin xyz="-0.020095249652862544332 0.025757756134899473244 -0.034722403578460216134" rpy="0 -0 0" />
      <geometry>
        <mesh filename="package://robot_models/meshes/leap/palm_lower.stl"/>
      </geometry>
      <material name="palm_lower_material">
        <color rgba="0.60392156862745094426 0.14901960784313725283 0.14901960784313725283 1.0"/>
      </material>
    </visual>
    <collision>
      <origin xyz="-0.04859524965286255 -0.03710692886510053 -0.011722403528460216" rpy="0 -0 0" />
      <geometry>
        <box size="0.10300000000000001 0.12572937 0.0460000001"/>
      </geometry>
    </collision>
    <inertial>
      <origin xyz="0 0 0" rpy="0 0 0"/>
      <mass value="0.237" />
      <inertia ixx="0.000354094" ixy="-0.000001193" ixz="-0.000002445" iyy="0.000260915" iyz="-0.000002905" izz="0.000529257" />
    </inertial>
  </link>

  <link name="mcp_joint">
    <visual>
      <origin xyz="0.0084069022611744960438 0.0077662438597169954416 0.014657354985032912051" rpy="1.6375789613220999807e-15 -1.0210473302491019535e-30 1.7177968783327987474e-31" />
      <geometry>
        <mesh filename="package://robot_models/meshes/leap/mcp_joint.stl"/>
      </geometry>
      <material name="mcp_joint_material">
        <color rgba="0.86666666666666669627 0.86666666666666669627 0.050980392156862744391 1.0"/>
      </material>
    </visual>
    <collision>
      <origin xyz="-0.027217272738825505 0.039799998859716995 0.018749999985032913" rpy="1.6375789613220999807e-15 -1.0210473302491019535e-30 1.7177968783327987474e-31" />
      <geometry>
        <box size="0.031565449999999995 0.04559999 0.02850001"/>
      </geometry>
    </collision>
    <collision>
      <origin xyz="0 0.006531743859716996 0.014499999985032912" rpy="1.6375789613220999807e-15 -1.0210473302491019535e-30 1.7177968783327987474e-31" />
      <geometry>
        <box size="0.02 0.02893652 0.03459999"/>
      </geometry>
    </collision>
    <inertial>
      <origin xyz="0 0 0" rpy="0 0 0"/>
      <mass value="0.044" />
      <inertia ixx="0.000011499" ixy="0.000003049" ixz="0.000000121" iyy="0.000007796" iyz="0.000000112" izz="0.000014759" />
    </inertial>
  </link>

  <link name="pip">
    <visual>
      <origin xyz="0.0096433630922713280131 0.00029999999999998951117 0.00078403401041737645627" rpy="-1.570796326794896558 -1.570796326794896336 0" />
      <geometry>
        <mesh filename="package://robot_models/meshes/leap/pip.stl"/>
      </geometry>
      <material name="pip_material">
        <color rgba="0.74901960784313725839 0.74901960784313725839 0.74901960784313725839 1.0"/>
      </material>
    </visual>
    <collision>
      <origin xyz="0.007500003092271327 0.0002999999999999894 -0.011499995989582625" rpy="-1.570796326794896558 -1.570796326794896336 0" />
      <geometry>
        <box size="0.023 0.034 0.0295309"/>
      </geometry>
    </collision>
    <inertial>
      <origin xyz="0 0 0" rpy="0 0 0"/>
      <mass value="0.032" />
      <inertia ixx="0.000004798" ixy="0.000000012" ixz="0.000000004" iyy="0.000002862" iyz="0.000000011" izz="0.000004234" />
    </inertial>
  </link>

  <link name="dip">
    <visual>
      <origin xyz="0.021133352895225002849 -0.0084321191467048792201 0.0097850881620952408213" rpy="-3.141592653589793116 4.5075111242164408299e-32 4.4395481053923607589e-32" />
      <geometry>
        <mesh filename="package://robot_models/meshes/leap/dip.stl"/>
      </geometry>
      <material name="dip_material">
        <color rgba="0.86666666666666669627 0.86666666666666669627 0.050980392156862744391 1.0"/>
      </material>
    </visual>
    <collision>
      <origin xyz="0.007500002895225002 -0.03459999914670488 0.014200003162095238" rpy="-3.141592653589793116 4.5075111242164408299e-32 4.4395481053923607589e-32" />
      <geometry>
        <box size="0.034 0.023 0.02953089"/>
      </geometry>
    </collision>
    <collision>
      <origin xyz="2.8952250007152625e-09 -0.00759779914670488 0.01449999816209524" rpy="-3.141592653589793116 4.5075111242164408299e-32 4.4395481053923607589e-32" />
      <geometry>
        <box size="0.02 0.03106864 0.0346"/>
      </geometry>
    </collision>
    <inertial>
      <origin xyz="0 0 0" rpy="0 0 0"/>
      <mass value="0.037" />
      <inertia ixx="0.000005542" ixy="-0.000000607" ixz="-0.000000017" iyy="0.000005727" iyz="-0.000000023" izz="0.000006682" />
    </inertial>
  </link>

  <link name="fingertip">
    <visual>
      <origin xyz="0.013286424108533503169 -0.0061142383865419869249 0.014499999999999497666" rpy="3.141592653589793116 1.1993117970061734707e-33 4.4395481053923607589e-32" />
      <geometry>
        <mesh filename="package://robot_models/meshes/leap/fingertip.stl"/>
      </geometry>
      <material name="fingertip_material">
        <color rgba="0.86666666666666669627 0.86666666666666669627 0.050980392156862744391 1.0"/>
      </material>
    </visual>
    <collision>
      <origin xyz="-0.000799055891466496 -0.03481634338654199 0.014499999999999501" rpy="3.141592653589793116 1.1993117970061734707e-33 4.4395481053923607589e-32" />
      <geometry>
        <box size="0.02059812 0.02936731 0.024"/>
      </geometry>
    </collision>
    <collision>
      <origin xyz="-0.00021593089146649744 -0.006088858386541987 0.014499999999999498" rpy="3.141592653589793116 1.1993117970061734707e-33 4.4395481053923607589e-32" />
      <geometry>
        <box size="0.020431869999999998 0.02805076 0.0346"/>
      </geometry>
    </collision>
    <inertial>
      <origin xyz="0 0 0" rpy="0 0 0"/>
      <mass value="0.016" />
      <inertia ixx="1.9179185288481334e-05" ixy="0" ixz="0" iyy="1.3337100633792e-05" iyz="0" izz="1.7156285922273336e-05" />
    </inertial>
  </link>



  <link name="mcp_joint_2">
    <visual>
      <origin xyz="0.0084069022611744960438 0.0077662438597169954416 0.014657354985032912051" rpy="1.6375789613220999807e-15 -1.0210473302491019535e-30 1.7177968783327987474e-31" />
      <geometry>
        <mesh filename="package://robot_models/meshes/leap/mcp_joint.stl"/>
      </geometry>
      <material name="mcp_joint_material">
        <color rgba="0.86666666666666669627 0.86666666666666669627 0.050980392156862744391 1.0"/>
      </material>
    </visual>
    <collision>
      <origin xyz="-0.027217272738825505 0.039799998859716995 0.018749999985032913" rpy="1.6375789613220999807e-15 -1.0210473302491019535e-30 1.7177968783327987474e-31" />
      <geometry>
        <box size="0.031565449999999995 0.04559999 0.02850001"/>
      </geometry>
    </collision>
    <collision>
      <origin xyz="0 0.006531743859716996 0.014499999985032912" rpy="1.6375789613220999807e-15 -1.0210473302491019535e-30 1.7177968783327987474e-31" />
      <geometry>
        <box size="0.02 0.02893652 0.03459999"/>
      </geometry>
    </collision>
    <inertial>
      <origin xyz="0 0 0" rpy="0 0 0"/>
      <mass value="0.044" />
      <inertia ixx="0.000011499" ixy="0.000003049" ixz="0.000000121" iyy="0.000007796" iyz="0.000000112" izz="0.000014759" />
    </inertial>
  </link>

  <link name="pip_2">
    <visual>
      <origin xyz="0.0096433630922713280131 0.00029999999999998951117 0.00078403401041737645627" rpy="-1.570796326794896558 -1.570796326794896336 0" />
      <geometry>
        <mesh filename="package://robot_models/meshes/leap/pip.stl"/>
      </geometry>
      <material name="pip_material">
        <color rgba="0.74901960784313725839 0.74901960784313725839 0.74901960784313725839 1.0"/>
      </material>
    </visual>
    <collision>
      <origin xyz="0.007500003092271327 0.0002999999999999894 -0.011499995989582625" rpy="-1.570796326794896558 -1.570796326794896336 0" />
      <geometry>
        <box size="0.023 0.034 0.0295309"/>
      </geometry>
    </collision>
    <inertial>
      <origin xyz="0 0 0" rpy="0 0 0"/>
      <mass value="0.032" />
      <inertia ixx="0.000004798" ixy="0.000000012" ixz="0.000000004" iyy="0.000002862" iyz="0.000000011" izz="0.000004234" />
    </inertial>
  </link>

  <link name="dip_2">
    <visual>
      <origin xyz="0.021133352895225002849 -0.0084321191467048792201 0.0097850881620952408213" rpy="-3.141592653589793116 4.5075111242164408299e-32 4.4395481053923607589e-32" />
      <geometry>
        <mesh filename="package://robot_models/meshes/leap/dip.stl"/>
      </geometry>
      <material name="dip_material">
        <color rgba="0.86666666666666669627 0.86666666666666669627 0.050980392156862744391 1.0"/>
      </material>
    </visual>
    <collision>
      <origin xyz="0.007500002895225002 -0.03459999914670488 0.014200003162095238" rpy="-3.141592653589793116 4.5075111242164408299e-32 4.4395481053923607589e-32" />
      <geometry>
        <box size="0.034 0.023 0.02953089"/>
      </geometry>
    </collision>
    <collision>
      <origin xyz="2.8952250007152625e-09 -0.00759779914670488 0.01449999816209524" rpy="-3.141592653589793116 4.5075111242164408299e-32 4.4395481053923607589e-32" />
      <geometry>
        <box size="0.02 0.03106864 0.0346"/>
      </geometry>
    </collision>
    <inertial>
      <origin xyz="0 0 0" rpy="0 0 0"/>
      <mass value="0.037" />
      <inertia ixx="0.000005542" ixy="-0.000000607" ixz="-0.000000017" iyy="0.000005727" iyz="-0.000000023" izz="0.000006682" />
    </inertial>
  </link>

  <link name="fingertip_2">
    <visual>
      <origin xyz="0.013286424108533503169 -0.0061142383865419869249 0.014499999999999497666" rpy="3.141592653589793116 1.1993117970061734707e-33 4.4395481053923607589e-32" />
      <geometry>
        <mesh filename="package://robot_models/meshes/leap/fingertip.stl"/>
      </geometry>
      <material name="fingertip_material">
        <color rgba="0.86666666666666669627 0.86666666666666669627 0.050980392156862744391 1.0"/>
      </material>
    </visual>
    <collision>
      <origin xyz="-0.000799055891466496 -0.03481634338654199 0.014499999999999501" rpy="3.141592653589793116 1.1993117970061734707e-33 4.4395481053923607589e-32" />
      <geometry>
        <box size="0.02059812 0.02936731 0.024"/>
      </geometry>
    </collision>
    <collision>
      <origin xyz="-0.00021593089146649744 -0.006088858386541987 0.014499999999999498" rpy="3.141592653589793116 1.1993117970061734707e-33 4.4395481053923607589e-32" />
      <geometry>
        <box size="0.020431869999999998 0.02805076 0.0346"/>
      </geometry>
    </collision>
    <inertial>
      <origin xyz="0 0 0" rpy="0 0 0"/>
      <mass value="0.016" />
      <inertia ixx="1.9179185288481334e-05" ixy="0" ixz="0" iyy="1.3337100633792e-05" iyz="0" izz="1.7156285922273336e-05" />
    </inertial>
  </link>



  <link name="mcp_joint_3">
    <visual>
      <origin xyz="0.0084069022611744960438 0.0077662438597169954416 0.014657354985032912051" rpy="1.6375789613220999807e-15 -1.0210473302491019535e-30 1.7177968783327987474e-31" />
      <geometry>
        <mesh filename="package://robot_models/meshes/leap/mcp_joint.stl"/>
      </geometry>
      <material name="mcp_joint_material">
        <color rgba="0.86666666666666669627 0.86666666666666669627 0.050980392156862744391 1.0"/>
      </material>
    </visual>
    <collision>
      <origin xyz="-0.027217272738825505 0.039799998859716995 0.018749999985032913" rpy="1.6375789613220999807e-15 -1.0210473302491019535e-30 1.7177968783327987474e-31" />
      <geometry>
        <box size="0.031565449999999995 0.04559999 0.02850001"/>
      </geometry>
    </collision>
    <collision>
      <origin xyz="0 0.006531743859716996 0.014499999985032912" rpy="1.6375789613220999807e-15 -1.0210473302491019535e-30 1.7177968783327987474e-31" />
      <geometry>
        <box size="0.02 0.02893652 0.03459999"/>
      </geometry>
    </collision>
    <inertial>
      <origin xyz="0 0 0" rpy="0 0 0"/>
      <mass value="0.044" />
      <inertia ixx="0.000011499" ixy="0.000003049" ixz="0.000000121" iyy="0.000007796" iyz="0.000000112" izz="0.000014759" />
    </inertial>
  </link>

  <link name="pip_3">
    <visual>
      <origin xyz="0.0096433630922713280131 0.00029999999999998951117 0.00078403401041737645627" rpy="-1.570796326794896558 -1.570796326794896336 0" />
      <geometry>
        <mesh filename="package://robot_models/meshes/leap/pip.stl"/>
      </geometry>
      <material name="pip_material">
        <color rgba="0.74901960784313725839 0.74901960784313725839 0.74901960784313725839 1.0"/>
      </material>
    </visual>
    <collision>
      <origin xyz="0.007500003092271327 0.0002999999999999894 -0.011499995989582625" rpy="-1.570796326794896558 -1.570796326794896336 0" />
      <geometry>
        <box size="0.023 0.034 0.0295309"/>
      </geometry>
    </collision>
    <inertial>
      <origin xyz="0 0 0" rpy="0 0 0"/>
      <mass value="0.032" />
      <inertia ixx="0.000004798" ixy="0.000000012" ixz="0.000000004" iyy="0.000002862" iyz="0.000000011" izz="0.000004234" />
    </inertial>
  </link>

  <link name="dip_3">
    <visual>
      <origin xyz="0.021133352895225002849 -0.0084321191467048792201 0.0097850881620952408213" rpy="-3.141592653589793116 4.5075111242164408299e-32 4.4395481053923607589e-32" />
      <geometry>
        <mesh filename="package://robot_models/meshes/leap/dip.stl"/>
      </geometry>
      <material name="dip_material">
        <color rgba="0.86666666666666669627 0.86666666666666669627 0.050980392156862744391 1.0"/>
      </material>
    </visual>
    <collision>
      <origin xyz="0.007500002895225002 -0.03459999914670488 0.014200003162095238" rpy="-3.141592653589793116 4.5075111242164408299e-32 4.4395481053923607589e-32" />
      <geometry>
        <box size="0.034 0.023 0.02953089"/>
      </geometry>
    </collision>
    <collision>
      <origin xyz="2.8952250007152625e-09 -0.00759779914670488 0.01449999816209524" rpy="-3.141592653589793116 4.5075111242164408299e-32 4.4395481053923607589e-32" />
      <geometry>
        <box size="0.02 0.03106864 0.0346"/>
      </geometry>
    </collision>
    <inertial>
      <origin xyz="0 0 0" rpy="0 0 0"/>
      <mass value="0.037" />
      <inertia ixx="0.000005542" ixy="-0.000000607" ixz="-0.000000017" iyy="0.000005727" iyz="-0.000000023" izz="0.000006682" />
    </inertial>
  </link>

  <link name="fingertip_3">
    <visual>
      <origin xyz="0.013286424108533503169 -0.0061142383865419869249 0.014499999999999497666" rpy="3.141592653589793116 1.1993117970061734707e-33 4.4395481053923607589e-32" />
      <geometry>
        <mesh filename="package://robot_models/meshes/leap/fingertip.stl"/>
      </geometry>
      <material name="fingertip_material">
        <color rgba="0.86666666666666669627 0.86666666666666669627 0.050980392156862744391 1.0"/>
      </material>
    </visual>
    <collision>
      <origin xyz="-0.000799055891466496 -0.03481634338654199 0.014499999999999501" rpy="3.141592653589793116 1.1993117970061734707e-33 4.4395481053923607589e-32" />
      <geometry>
        <box size="0.02059812 0.02936731 0.024"/>
      </geometry>
    </collision>
    <collision>
      <origin xyz="-0.00021593089146649744 -0.006088858386541987 0.014499999999999498" rpy="3.141592653589793116 1.1993117970061734707e-33 4.4395481053923607589e-32" />
      <geometry>
        <box size="0.020431869999999998 0.02805076 0.0346"/>
      </geometry>
    </collision>
    <inertial>
      <origin xyz="0 0 0" rpy="0 0 0"/>
      <mass value="0.016" />
      <inertia ixx="1.9179185288481334e-05" ixy="0" ixz="0" iyy="1.3337100633792e-05" iyz="0" izz="1.7156285922273336e-05" />
    </inertial>
  </link>



  <link name="pip_4">
    <visual>
      <origin xyz="-0.0053566369077286714317 0.00029999999999999991951 0.00078403401041737819099" rpy="-1.570796326794896558 -1.570796326794896336 0" />
      <geometry>
        <mesh filename="package://robot_models/meshes/leap/pip.stl"/>
      </geometry>
      <material name="pip_material">
        <color rgba="0.74901960784313725839 0.74901960784313725839 0.74901960784313725839 1.0"/>
      </material>
    </visual>
    <collision>
      <origin xyz="-0.007499996907728673 0.0002999999999999998 -0.011499995989582623" rpy="-1.570796326794896558 -1.570796326794896336 0" />
      <geometry>
        <box size="0.023 0.034 0.0295309"/>
      </geometry>
    </collision>
    <inertial>
      <origin xyz="0 0 0" rpy="0 0 0"/>
      <mass value="0.032" />
      <inertia ixx="0.000004798" ixy="0.000000012" ixz="0.000000004" iyy="0.000002862" iyz="0.000000011" izz="0.000004234" />
    </inertial>
  </link>

  <link name="thumb_pip">
    <visual>
      <origin xyz="0.011961920770611186859 -5.3082538364890297089e-16 -0.015852648956664199681" rpy="1.570796326794896558 0 0" />
      <geometry>
        <mesh filename="package://robot_models/meshes/leap/thumb_pip.stl"/>
      </geometry>
      <material name="thumb_pip_material">
        <color rgba="0.86666666666666669627 0.86666666666666669627 0.050980392156862744391 1.0"/>
      </material>
    </visual>
    <collision>
      <origin xyz="7.706111877087141e-10 -5.306181495298747e-16 -0.0124682589566642" rpy="1.570796326794896558 0 0" />
      <geometry>
        <box size="0.02 0.02493652 0.0346"/>
      </geometry>
    </collision>
    <inertial>
      <origin xyz="0 0 0" rpy="0 0 0"/>
      <mass value="0.003" />
      <inertia ixx="0.000000593" ixy="0" ixz="0" iyy="0.000000549" iyz="0" izz="0.000000224" />
    </inertial>
  </link>

  <link name="thumb_dip">
    <visual>
      <origin xyz="0.043968715707239175439 0.057952952973709198625 -0.0086286764493694757122" rpy="1.9428902930940098942e-16 3.2751579226442200773e-15 0" />
      <geometry>
        <mesh filename="package://robot_models/meshes/leap/thumb_dip.stl"/>
      </geometry>
      <material name="thumb_dip_material">
        <color rgba="0.86666666666666669627 0.86666666666666669627 0.050980392156862744391 1.0"/>
      </material>
    </visual>
    <collision>
      <origin xyz="-0.004250004292760824 0.0225182629737092 -0.014299996449369475" rpy="1.9428902930940098942e-16 3.2751579226442200773e-15 0" />
      <geometry>
        <box size="0.028499999999999998 0.06403652 0.0346"/>
      </geometry>
    </collision>
    <inertial>
      <origin xyz="0 0 0" rpy="0 0 0"/>
      <mass value="0.038" />
      <inertia ixx="0.000008474" ixy="0.000000241" ixz="0.000000026" iyy="0.000003841" iyz="0.000000025" izz="0.000007679" />
    </inertial>
  </link>

  <link name="thumb_fingertip">
    <visual>
      <origin xyz="0.062559538462667388381 0.078459682911396988469 0.048992911807332215068" rpy="0 0 0" />
      <geometry>
        <mesh filename="package://robot_models/meshes/leap/thumb_fingertip.stl"/>
      </geometry>
      <material name="thumb_fingertip_material">
        <color rgba="0.60392156862745094426 0.14901960784313725283 0.14901960784313725283 1.0"/>
      </material>
    </visual>
    <collision>
      <origin xyz="0.0042499984626673815 -0.010049997088603019 -0.014299998192667779" rpy="0 0 0" />
      <geometry>
        <box size="0.028500000000000004 0.03910000000000001 0.032999999999999995"/>
      </geometry>
    </collision>
    <collision>
      <origin xyz="-0.0007990565373326153 -0.046100002088603015 -0.01430000319266779" rpy="0 0 0" />
      <geometry>
        <box size="0.020598110000000003 0.03200000999999998 0.024000010000000002"/>
      </geometry>
    </collision>
    <inertial>
      <origin xyz="0 0 0" rpy="0 0 0"/>
      <mass value="0.049" />
      <inertia ixx="0.000020372" ixy="-0.000000489" ixz="-0.00000003" iyy="0.000004336" iyz="-0.000000097" izz="0.000019845" />
    </inertial>
  </link>

  <joint name="j12" type="revolute">
    <origin xyz="-0.069395249652862533996 -0.0012422438651005258004 -0.021622403578460215601" rpy="0 1.5707963267948956698 0" />
    <parent link="hand_base_link" />
    <child link="pip_4" />
    <axis xyz="0 0 -1"/>
    <limit effort="0.95" velocity="8.48" lower = "-0.349" upper = "2.094"/>
  </joint>

  <joint name="j13" type="revolute">
    <origin xyz="-2.7755575615628913511e-17 0.014300000000000005415 -0.013000000000000011546" rpy="1.5707963267948958919 -1.570796326794896336 0" />
    <parent link="pip_4" />
    <child link="thumb_pip" />
    <axis xyz="0 0 -1"/>
    <limit effort="0.95" velocity="8.48" lower = "-0.47" upper = "2.443"/>
  </joint>

  <joint name="j14" type="revolute">
    <origin xyz="0 0.014499999999999966041 -0.017000000000000053263" rpy="-1.570796326794896558 0 0" />
    <parent link="thumb_pip" />
    <child link="thumb_dip" />
    <axis xyz="0 0 -1"/>
    <limit effort="0.95" velocity="8.48" lower = "-1.20" upper = "1.90"/>
  </joint>

  <joint name="j15" type="revolute">
    <origin xyz="-1.249000902703301108e-16 0.046599999999999863753 0.00019999999999997710581" rpy="0 0 3.141592653589793116" />
    <parent link="thumb_dip" />
    <child link="thumb_fingertip" />
    <axis xyz="0 0 -1"/>
    <limit effort="0.95" velocity="8.48" lower = "-1.34" upper = "1.88"/>
  </joint>

  <joint name="j0" type="revolute">
    <origin xyz="-0.012200000000000007713 0.038099999999999994982 0.014500000000000000736" rpy="-1.570796326794896558 -1.0065212660796336576e-15 1.5707963267948943376" />
    <parent link="mcp_joint" />
    <child link="pip" />
    <axis xyz="0 0 -1"/>
    <limit effort="0.95" velocity="8.48" lower = "-1.047" upper = "1.047"/>
  </joint>

  <joint name="j1" type="revolute">
    <origin xyz="-0.0070952496528625457958 0.023057756134899472233 -0.01872240357846021927" rpy="1.5707963267948950037 1.5707963267948945596 0" />
    <parent link="hand_base_link" />
    <child link="mcp_joint" />
    <axis xyz="0 0 -1"/>
    <limit effort="0.95" velocity="8.48" lower = "-0.314" upper = "2.23"/>
  </joint>

  <joint name="j2" type="revolute">
    <origin xyz="0.01499999999999996822 0.014299999999999904801 -0.012999999999999824196" rpy="1.5707963267948958919 -1.570796326794896336 0" />
    <parent link="pip" />
    <child link="dip" />
    <axis xyz="0 0 -1"/>
    <limit effort="0.95" velocity="8.48" lower = "-0.506" upper = "1.885"/>
  </joint>

  <joint name="j3" type="revolute">
    <origin xyz="-4.0880582495572692636e-09 -0.036100004210367367397 0.00020000000000007858714" rpy="4.5935029425113685044e-17 -2.8730071914463794583e-16 4.4395481053923607589e-32" />
    <parent link="dip" />
    <child link="fingertip" />
    <axis xyz="0 0 -1"/>
    <limit effort="0.95" velocity="8.48" lower = "-0.366" upper = "2.042"/>
  </joint>

  <joint name="j8" type="revolute">
    <origin xyz="-0.012200000000000004244 0.038100000000000001921 0.014499999999999999001" rpy="-1.570796326794896558 -1.0065212660796360242e-15 1.5707963267948943376" />
    <parent link="mcp_joint_3" />
    <child link="pip_3" />
    <axis xyz="0 0 -1"/>
    <limit effort="0.95" velocity="8.48" lower = "-1.047" upper = "1.047"/>
  </joint>

  <joint name="j9" type="revolute">
    <origin xyz="-0.0070952454426398371343 -0.067842243865100515521 -0.018722407666402932774" rpy="1.5707963267948950037 1.5707963267948945596 0" />
    <parent link="hand_base_link" />
    <child link="mcp_joint_3" />
    <axis xyz="0 0 -1"/>
    <limit effort="0.95" velocity="8.48" lower = "-0.314" upper = "2.23"/>
  </joint>

  <joint name="j10" type="revolute">
    <origin xyz="0.014999999999999971689 0.014299999999999951639 -0.012999999999999959505" rpy="1.5707963267948958919 -1.570796326794896336 0" />
    <parent link="pip_3" />
    <child link="dip_3" />
    <axis xyz="0 0 -1"/>
    <limit effort="0.95" velocity="8.48" lower = "-0.506" upper = "1.885"/>
  </joint>

  <joint name="j11" type="revolute">
    <origin xyz="9.7144514654701197287e-17 -0.036099999999999868305 0.00020000000000007511769" rpy="4.5935029425113685044e-17 -2.8730071914463799514e-16 1.5565411607615035382e-32" />
    <parent link="dip_3" />
    <child link="fingertip_3" />
    <axis xyz="0 0 -1"/>
    <limit effort="0.95" velocity="8.48" lower = "-0.366" upper = "2.042"/>
  </joint>

  <joint name="j4" type="revolute">
    <origin xyz="-0.012200000000000019856 0.038099999999999981104 0.01450000000000000594" rpy="-1.570796326794896558 -1.0065212760057939085e-15 1.5707963267948943376" />
    <parent link="mcp_joint_2" />
    <child link="pip_2" />
    <axis xyz="0 0 -1"/>
    <limit effort="0.95" velocity="8.48" lower = "-1.047" upper = "1.047"/>
  </joint>

  <joint name="j5" type="revolute">
    <origin xyz="-0.0070952496528625388569 -0.022392243865100525113 -0.018722403578460229678" rpy="1.570796326794896558 1.570796326794896558 0" />
    <parent link="hand_base_link" />
    <child link="mcp_joint_2" />
    <axis xyz="0 0 -1"/>
    <limit effort="0.95" velocity="8.48" lower = "-0.314" upper = "2.23"/>
  </joint>

  <joint name="j6" type="revolute">
    <origin xyz="0.014999999999999975159 0.014300000000000000211 -0.013000000000000018485" rpy="1.5707963267948958919 -1.570796326794896336 0" />
    <parent link="pip_2" />
    <child link="dip_2" />
    <axis xyz="0 0 -1"/>
    <limit effort="0.95" velocity="8.48" lower = "-0.506" upper = "1.885"/>
  </joint>

  <joint name="j7" type="revolute">
    <origin xyz="1.0061396160665481148e-16 -0.036099999999999854428 0.00020000000000007858714" rpy="4.5935029425113654229e-17 -2.8730071914463794583e-16 1.4408183216511868558e-31" />
    <parent link="dip_2" />
    <child link="fingertip_2" />
    <axis xyz="0 0 -1"/>
    <limit effort="0.95" velocity="8.48" lower = "-0.366" upper = "2.042"/>
  </joint>

</robot>
